<?xml version="1.0"?>
<robot xmlns:xacro="http://wiki.ros.org/xacro">
    <xacro:include filename="$(find kuka_common)/urdf/common_constants.xacro"/>
    <xacro:include filename="$(find kuka_common)/urdf/common_materials.xacro"/>
    <xacro:include filename="$(find kuka_common)/urdf/kuka.ros2_control.xacro"/>
    <xacro:include filename="$(find kuka_kr10r1100sixx_cell_description)/urdf/kr10_macro.ros2_control.xacro"/>

    <xacro:macro name="kuka_kr10r1100sixx" params="prefix initial_positions_file robot_ip robot_port use_fake_hardware">
        <link name="${prefix}table_link">
            <visual>
                <origin xyz="0 0 0" rpy="0 0 0"/>
                <geometry>
                    <mesh filename="package://kuka_kr10r1100sixx_cell_description/meshes/kr10r1100sixx_cell/visual/table0.001.stl"/>
                </geometry>
                <xacro:material_kuka_ral_silver_gray/>
            </visual>
            <collision>
                <origin xyz="0 0 0" rpy="0 0 0"/>
                <geometry>
                    <mesh filename="package://kuka_kr10r1100sixx_cell_description/meshes/kr10r1100sixx_cell/collision/table0.001.stl"/>
                </geometry>
            </collision>
        </link>
        <link name="${prefix}base_link">
            <visual>
                <origin xyz="0 0 0" rpy="0 0 0"/>
                <geometry>
                    <mesh filename="package://kuka_kr10_description/meshes/kr10r1100sixx/visual/base_link.stl"/>
                </geometry>
                <xacro:material_kuka_black/>
            </visual>
            <collision>
                <origin xyz="0 0 0" rpy="0 0 0"/>
                <geometry>
                    <mesh filename="package://kuka_kr10_description/meshes/kr10r1100sixx/collision/base_link.stl"/>
                </geometry>
            </collision>
        </link>
        <link name="${prefix}link_1">
            <visual>
                <origin xyz="0 0 0" rpy="0 0 0"/>
                <geometry>
                    <mesh filename="package://kuka_kr10_description/meshes/kr10r1100sixx/visual/link_1.stl"/>
                </geometry>
                <xacro:material_kuka_orange/>
            </visual>
            <collision>
                <origin xyz="0 0 0" rpy="0 0 0"/>
                <geometry>
                    <mesh filename="package://kuka_kr10_description/meshes/kr10r1100sixx/collision/link_1.stl"/>
                </geometry>
            </collision>
        </link>
        <link name="${prefix}link_2">
            <visual>
                <origin xyz="0 0 0" rpy="0 0 0"/>
                <geometry>
                    <mesh filename="package://kuka_kr10_description/meshes/kr10r1100sixx/visual/link_2.stl"/>
                </geometry>
                <xacro:material_kuka_orange/>
            </visual>
            <collision>
                <origin xyz="0 0 0" rpy="0 0 0"/>
                <geometry>
                    <mesh filename="package://kuka_kr10_description/meshes/kr10r1100sixx/collision/link_2.stl"/>
                </geometry>
            </collision>
        </link>
        <link name="${prefix}link_3">
            <visual>
                <origin xyz="0 0 0" rpy="0 0 0"/>
                <geometry>
                    <mesh filename="package://kuka_kr10_description/meshes/kr10r1100sixx/visual/link_3.stl"/>
                </geometry>
                <xacro:material_kuka_orange/>
            </visual>
            <collision>
                <origin xyz="0 0 0" rpy="0 0 0"/>
                <geometry>
                    <mesh filename="package://kuka_kr10_description/meshes/kr10r1100sixx/collision/link_3.stl"/>
                </geometry>
            </collision>
        </link>
        <link name="${prefix}link_4">
            <visual>
                <origin xyz="0 0 0" rpy="0 0 0"/>
                <geometry>
                    <mesh filename="package://kuka_kr10_description/meshes/kr10r1100sixx/visual/link_4.stl"/>
                </geometry>
                <xacro:material_kuka_orange/>
            </visual>
            <collision>
                <origin xyz="0 0 0" rpy="0 0 0"/>
                <geometry>
                    <mesh filename="package://kuka_kr10_description/meshes/kr10r1100sixx/collision/link_4.stl"/>
                </geometry>
            </collision>
        </link>
        <link name="${prefix}link_5">
            <visual>
                <origin xyz="0 0 0" rpy="0 0 0"/>
                <geometry>
                    <mesh filename="package://kuka_kr10_description/meshes/kr10r1100sixx/visual/link_5.stl"/>
                </geometry>
                <xacro:material_kuka_orange/>
            </visual>
            <collision>
                <origin xyz="0 0 0" rpy="0 0 0"/>
                <geometry>
                    <mesh filename="package://kuka_kr10_description/meshes/kr10r1100sixx/collision/link_5.stl"/>
                </geometry>
            </collision>
        </link>
        <link name="${prefix}link_6">
            <visual>
                <origin xyz="0 0 0" rpy="0 0 0"/>
                <geometry>
                    <mesh filename="package://kuka_kr10_description/meshes/kr10r1100sixx/visual/link_6.stl"/>
                </geometry>
                <xacro:material_kuka_pedestal/>
            </visual>
            <collision>
                <origin xyz="0 0 0" rpy="0 0 0"/>
                <geometry>
                    <mesh filename="package://kuka_kr10_description/meshes/kr10r1100sixx/collision/link_6.stl"/>
                </geometry>
            </collision>
        </link>
        <link name="${prefix}container">
            <visual>
                <origin xyz="0 0 0" rpy="0 0 0"/>
                <geometry>
                    <mesh filename="package://kuka_kr10r1100sixx_cell_description/meshes/kr10r1100sixx_cell/visual/container_x07.stl"/>
                </geometry>
                <xacro:material_kuka_ral_pearly_white/>
            </visual>
            <collision>
                <origin xyz="0 0 0" rpy="0 0 0"/>
                <geometry>
                    <mesh filename="package://kuka_kr10r1100sixx_cell_description/meshes/kr10r1100sixx_cell/collision/container_x07.stl"/>
                </geometry>
            </collision>
        </link>
        <link name="${prefix}shelf">
            <visual>
                <origin xyz="0 0 0" rpy="0 0 0"/>
                <geometry>
                    <mesh filename="package://kuka_kr10r1100sixx_cell_description/meshes/kr10r1100sixx_cell/visual/shelf_new.stl"/>
                </geometry>
                <xacro:material_kuka_ral_silver_gray/>
            </visual>
            <collision>
                <origin xyz="0 0 0" rpy="0 0 0"/>
                <geometry>
                    <mesh filename="package://kuka_kr10r1100sixx_cell_description/meshes/kr10r1100sixx_cell/collision/shelf_new.stl"/>
                </geometry>
            </collision>
        </link>
        
        <!-- Following REP199, this frame shall be use to attach EEF or other equipment -->
        <link name="${prefix}gripper_base">
            <visual>
                <origin xyz="0 0 0" rpy="0 ${radians(180)} ${radians(270)}"/>
                <geometry>
                    <mesh filename="package://kuka_kr10r1100sixx_cell_description/meshes/kr10r1100sixx_cell/visual/gripper_visual_base.stl"/>
                </geometry>
                <xacro:material_kuka_ral_silver_gray/>
            </visual>
            <collision>
                <origin xyz="0 0 0" rpy="0 ${radians(180)} ${radians(270)}"/>
                <geometry>
                    <mesh filename="package://kuka_kr10r1100sixx_cell_description/meshes/kr10r1100sixx_cell/collision/gripper_col_base.stl"/>
                </geometry>
            </collision>
        </link>
        <link name="${prefix}cylinder_back_left">
            <visual>
                <origin xyz="0 0 0" rpy="0 ${radians(180)} ${radians(270)}"/>
                <geometry>
                    <mesh filename="package://kuka_kr10r1100sixx_cell_description/meshes/kr10r1100sixx_cell/visual/cylinder_back_left.stl"/>
                </geometry>
                <xacro:material_kuka_ral_silver_gray/>
            </visual>
            <collision>
                <origin xyz="0 0 0" rpy="0 ${radians(180)} ${radians(270)}"/>
                <geometry>
                    <mesh filename="package://kuka_kr10r1100sixx_cell_description/meshes/kr10r1100sixx_cell/collision/cylinder_col_bl.stl"/>
                </geometry>
            </collision>
        </link>
        <link name="${prefix}cylinder_back_right">
            <visual>
                <origin xyz="0 0 0" rpy="0 ${radians(180)} ${radians(270)}"/>
                <geometry>
                    <mesh filename="package://kuka_kr10r1100sixx_cell_description/meshes/kr10r1100sixx_cell/visual/cylinder_back_right.stl"/>
                </geometry>
                <xacro:material_kuka_ral_silver_gray/>
            </visual>
            <collision>
                <origin xyz="0 0 0" rpy="0 ${radians(180)} ${radians(270)}"/>
                <geometry>
                    <mesh filename="package://kuka_kr10r1100sixx_cell_description/meshes/kr10r1100sixx_cell/collision/cylinder_col_br.stl"/>
                </geometry>
            </collision>
        </link>
        <link name="${prefix}cylinder_front_left">
            <visual>
                <origin xyz="0 0 0" rpy="0 ${radians(180)} ${radians(270)}"/>
                <geometry>
                    <mesh filename="package://kuka_kr10r1100sixx_cell_description/meshes/kr10r1100sixx_cell/visual/cylinder_front_left.stl"/>
                </geometry>
                <xacro:material_kuka_ral_silver_gray/>
            </visual>
            <collision>
                <origin xyz="0 0 0" rpy="0 ${radians(180)} ${radians(270)}"/>
                <geometry>
                    <mesh filename="package://kuka_kr10r1100sixx_cell_description/meshes/kr10r1100sixx_cell/collision/cylinder_col_fl.stl"/>
                </geometry>
            </collision>
        </link>
        <link name="${prefix}cylinder_front_right">
            <visual>
                <origin xyz="0 0 0" rpy="0 ${radians(180)} ${radians(270)}"/>
                <geometry>
                    <mesh filename="package://kuka_kr10r1100sixx_cell_description/meshes/kr10r1100sixx_cell/visual/cylinder_front_right.stl"/>
                </geometry>
                <xacro:material_kuka_ral_silver_gray/>
            </visual>
            <collision>
                <origin xyz="0 0 0" rpy="0 ${radians(180)} ${radians(270)}"/>
                <geometry>
                    <mesh filename="package://kuka_kr10r1100sixx_cell_description/meshes/kr10r1100sixx_cell/collision/cylinder_col_fr.stl"/>
                </geometry>
            </collision>
        </link>
        <link name="${prefix}tcp"/>
        <link name="${prefix}tcp_1"/>
        <link name="${prefix}tcp_2"/>
        <link name="${prefix}tcp_3"/>
        <link name="${prefix}tcp_4"/>
        <link name="${prefix}tcp_5"/>
        <link name="${prefix}tcp_6"/>
        <link name="${prefix}tcp_7"/>
        <!-- <link name="${prefix}package_gripper">
            <visual>
                <origin xyz="0 0 0" rpy="${radians(90)} 0 ${radians(90)}"/>
                <geometry>
                    <mesh filename="package://kuka_kr10r1100sixx_cell_description/meshes/kr10r1100sixx_cell/visual/PS_098601831.stl"/>
                </geometry>
                <xacro:material_kuka_ral_turquoise_blue/>
            </visual>
            <collision>
                <origin xyz="0 0 0" rpy="${radians(90)} 0 ${radians(90)}"/>
                <geometry>
                    <mesh filename="package://kuka_kr10r1100sixx_cell_description/meshes/kr10r1100sixx_cell/collision/PS_098601831.stl"/>
                </geometry>
            </collision>
        </link> -->
        

        <joint name="${prefix}joint_a0" type="fixed">
            <parent link="${prefix}table_link"/>
            <child link="${prefix}base_link"/>
            <origin xyz="0.2 0.4 0.965" rpy="0 0 0"/>
        </joint>
        <joint name="${prefix}joint_a1" type="revolute">
            <origin xyz="0 0 0.400" rpy="0 0 0"/>
            <parent link="${prefix}base_link"/>
            <child link="${prefix}link_1"/>
            <axis xyz="0 0 -1"/>
            <limit effort="0" lower="${radians(-170)}" upper="${radians(170)}" velocity="${radians(300)}"/>
        </joint>
        <joint name="${prefix}joint_a2" type="revolute">
            <origin xyz="0.025 0 0" rpy="0 0 0"/>
            <parent link="${prefix}link_1"/>
            <child link="${prefix}link_2"/>
            <axis xyz="0 1 0"/>
            <limit effort="0" lower="${radians(-190)}" upper="${radians(45)}" velocity="${radians(225)}"/>
        </joint>
        <joint name="${prefix}joint_a3" type="revolute">
            <origin xyz="0.560 0 0" rpy="0 0 0"/>
            <parent link="${prefix}link_2"/>
            <child link="${prefix}link_3"/>
            <axis xyz="0 1 0"/>
            <limit effort="0" lower="${radians(-120)}" upper="${radians(156)}" velocity="${radians(225)}"/>
        </joint>
        <joint name="${prefix}joint_a4" type="revolute">
            <origin xyz="0 0 0.035" rpy="0 0 0"/>
            <parent link="${prefix}link_3"/>
            <child link="${prefix}link_4"/>
            <axis xyz="-1 0 0"/>
            <limit effort="0" lower="${radians(-185)}" upper="${radians(185)}" velocity="${radians(381)}"/>
        </joint>
        <joint name="${prefix}joint_a5" type="revolute">
            <origin xyz="0.515 0 0" rpy="0 0 0"/>
            <parent link="${prefix}link_4"/>
            <child link="${prefix}link_5"/>
            <axis xyz="0 1 0"/>
            <limit effort="0" lower="${radians(-120)}" upper="${radians(120)}" velocity="${radians(311)}"/>
        </joint>
        <joint name="${prefix}joint_a6" type="revolute">
            <origin xyz="0.080 0 0" rpy="0 0 0"/>
            <parent link="${prefix}link_5"/>
            <child link="${prefix}link_6"/>
            <axis xyz="-1 0 0"/>
            <limit effort="0" lower="${radians(-350)}" upper="${radians(350)} " velocity="${radians(492)}"/>
        </joint>
        <joint name="${prefix}joint_b1" type="fixed">
            <parent link="${prefix}table_link"/>
            <child link="${prefix}container"/>
            <origin xyz="0.552 0.191 0.94" rpy="0 0 0"/>
        </joint>
        <joint name="${prefix}joint_b2" type="fixed">
            <parent link="${prefix}table_link"/>
            <child link="${prefix}shelf"/>
            <origin xyz="0.242 0.806 0.908" rpy="0 0 0"/>
        </joint>
        

        <!-- ROS base_link to KUKA $ROBROOT coordinate system transform -->
        <link name="${prefix}base"/>
        <joint name="${prefix}table_link-base" type="fixed">
            <origin xyz="0 0 0" rpy="0 0 0"/>
            <parent link="${prefix}table_link"/>
            <child link="${prefix}base"/>
        </joint>

        <!-- This frame corresponds to the $TOOL coordinate system in KUKA KRC controllers -->
        <!-- <link name="${prefix}tool"/> -->
        <joint name="${prefix}joint_gripper_base" type="fixed">
            <parent link="${prefix}link_6"/>
            <child link="${prefix}gripper_base"/>
            <origin xyz="0 0 0" rpy="0 0 0"/>
        </joint>
        <joint name="${prefix}joint_cylinder_back_left" type="prismatic">
            <parent link="${prefix}gripper_base"/>
            <child link="${prefix}cylinder_back_left"/>
            <origin xyz="0 0 0" rpy="0 0 0"/>
            <axis xyz="1 0 0"/>
            <limit effort="0" lower="0" upper="0.15" velocity="0.15"/>
        </joint>
        <joint name="${prefix}joint_cylinder_back_right" type="prismatic">
            <parent link="${prefix}gripper_base"/>
            <child link="${prefix}cylinder_back_right"/>
            <origin xyz="0 0 0" rpy="0 0 0"/>
            <axis xyz="1 0 0"/>
            <limit effort="0" lower="0" upper="0.15" velocity="0.15"/>
        </joint>
        <joint name="${prefix}joint_cylinder_front_left" type="prismatic">
            <parent link="${prefix}gripper_base"/>
            <child link="${prefix}cylinder_front_left"/>
            <origin xyz="0 0 0" rpy="0 0 0"/>
            <axis xyz="1 0 0"/>
            <limit effort="0" lower="0" upper="0.15" velocity="0.15"/>
        </joint>
        <joint name="${prefix}joint_cylinder_front_right" type="prismatic">
            <parent link="${prefix}gripper_base"/>
            <child link="${prefix}cylinder_front_right"/>
            <origin xyz="0 0 0" rpy="0 0 0"/>
            <axis xyz="1 0 0"/>
            <limit effort="0" lower="0" upper="0.15" velocity="0.15"/>
        </joint>
        <joint name="${prefix}joint_tcp" type="fixed">
            <parent link="${prefix}gripper_base"/>
            <child link="${prefix}tcp"/>
            <origin xyz="0 0 0" rpy="0 ${radians(270)} 0"/>
        </joint>
        <joint name="${prefix}joint_tcp_1" type="fixed">
            <parent link="${prefix}gripper_base"/>
            <child link="${prefix}tcp_1"/>
            <origin xyz="0.299 -0.0815 -0.0485" rpy="0 0 0"/>
        </joint>
        <joint name="${prefix}joint_tcp_2" type="fixed">
            <parent link="${prefix}gripper_base"/>
            <child link="${prefix}tcp_2"/>
            <origin xyz="0.299 0.0495 -0.0505" rpy="0 0 0"/> 
        </joint>
        <joint name="${prefix}joint_tcp_3" type="fixed">
            <parent link="${prefix}gripper_base"/>
            <child link="${prefix}tcp_3"/>
            <origin xyz="0.281 -0.106 0.075" rpy="0 0 0"/>
        </joint>
        <joint name="${prefix}joint_tcp_4" type="fixed">
            <parent link="${prefix}gripper_base"/>
            <child link="${prefix}tcp_4"/>
            <origin xyz="0.299 0.055 0.0585" rpy="0 0 0"/>
        </joint>
        <joint name="${prefix}joint_tcp_5" type="fixed">
            <parent link="${prefix}gripper_base"/>
            <child link="${prefix}tcp_5"/>
            <origin xyz="0.299 0.009 -0.049" rpy="0 0 0"/>
        </joint>
        <joint name="${prefix}joint_tcp_6" type="fixed">
            <parent link="${prefix}gripper_base"/>
            <child link="${prefix}tcp_6"/>
            <origin xyz="0.299 0.054 0.001" rpy="0 0 0"/>
        </joint>
        <joint name="${prefix}joint_tcp_7" type="fixed">
            <parent link="${prefix}gripper_base"/>
            <child link="${prefix}tcp_7"/>
            <origin xyz="0.299 0.015 0.001" rpy="0 0 0"/>
        </joint>
        <!-- <joint name="${prefix}joint_gripper_package" type="fixed">
            <parent link="${prefix}gripper_base"/>
            <child link="${prefix}package_gripper"/>
            <origin xyz="0.299 -0.1495 -0.0845" rpy="0 0 0"/>
        </joint> -->
        
        <xacro:kuka_ros2_control name="kuka_control" robot_prefix="${prefix}"
                                 initial_positions_file="${initial_positions_file}"
                                 robot_ip="${robot_ip}" robot_port="${robot_port}"
                                 use_fake_hardware="${use_fake_hardware}"/>
        <xacro:kr10_gripper_ros2_control name="gripper_control" prefix="${prefix}"/>
    </xacro:macro>
</robot>
